Workbook

Sheet all_prospects
A1: YEAR | B1: ROUND | C1: PLAYER | D1: RANKING | E1: POSITION | F1: TEAM | G1: LEAGUE | H1: NHL_EQUIVALENT | I1: GP | J1: G | K1: A | L1: PTS | M1: PIM | N1: NATIONALITY | O1: FLAG | P1: PLAYER_W_POSITION | Q1: Born | R1: HT | S1: WT | T1: S
A2: 2025 | C2: Matthew Schaefer | D2: 1 | E2: D | F2: Erie Otters | G2: OHL | H2: =VLOOKUP(G2, Sheet3!$A$2:$B$40, 2, FALSE) -> 0.3 | I2: 17 | J2: 7 | K2: 15 | L2: 22 | M2: 8 | N2: CANADA | O2: #VALUE! | P2: Matthew Schaefer (D) | Q2: 39330 | R2: 6'2" | S2: 183 | T2: L
A3: 2025 | C3: Michael Misa | D3: 2 | E3: F | F3: Saginaw Spirit | G3: OHL | H3: =VLOOKUP(G3, Sheet3!$A$2:$B$40, 2, FALSE) -> 0.3 | I3: 65 | J3: 62 | K3: 72 | L3: 134 | M3: 45 | N3: CANADA | O3: #VALUE! | P3: Michael Misa (C/LW) | Q3: 39129 | R3: 6'1" | S3: 185 | T3: L
A4: 2025 | C4: James Hagens | D4: 3 | E4: F | F4: Boston College | G4: NCAA | H4: =VLOOKUP(G4, Sheet3!$A$2:$B$40, 2, FALSE) -> 0.32 | I4: 37 | J4: 11 | K4: 26 | L4: 37 | M4: 24 | N4: USA | O4: #VALUE! | P4: James Hagens (C) | Q4: 39024 | R4: 5'11" | S4: 176 | T4: L
A5: 2025 | C5: Porter Martone | D5: 4 | E5: F | F5: Brampton Steelheads | G5: OHL | H5: =VLOOKUP(G5, Sheet3!$A$2:$B$40, 2, FALSE) -> 0.3 | I5: 57 | J5: 37 | K5: 61 | L5: 98 | M5: 74 | N5: CANADA | O5: #VALUE! | P5: Porter Martone (RW) | Q5: 39016 | R5: 6'3" | S5: 207 | T5: R
A6: 2025 | C6: Anton Frondell | D6: =VLOOKUP(C6, Rankings!$A$2:$B$101, 2, FALSE) -> 5 | E6: F | F6: DjurgÃ¥rdens IF | G6: HockeyAllsvenskan | H6: =VLOOKUP(G6, Sheet3!$A$2:$B$40, 2, FALSE) -> 0.41 | I6: 29 | J6: 11 | K6: 14 | L6: 25 | M6: 16 | N6: SWEDEN | O6: #VALUE! | P6: Anton Frondell (C) | Q6: 39209 | R6: 6'0" | S6: 196 | T6: L
A7: 2025 | C7: Roger McQueen | D7: 6 | E7: F | F7: Brandon Wheat Kings | G7: WHL | H7: =VLOOKUP(G7, Sheet3!$A$2:$B$40, 2, FALSE) -> 0.29 | I7: 17 | J7: 10 | K7: 10 | L7: 20 | M7: 40 | N7: CANADA | O7: #VALUE! | P7: Roger McQueen (F) | Q7: 38992 | R7: 6'5" | S7: 192 | T7: R
A8: 2025 | C8: Victor Eklund | D8: =VLOOKUP(C8, Rankings!$A$2:$B$101, 2, FALSE) -> 7 | E8: F | F8: DjurgÃ¥rdens IF | G8: HockeyAllsvenskan | H8: =VLOOKUP(G8, Sheet3!$A$2:$B$40, 2, FALSE) -> 0.41 | I8: 42 | J8: 19 | K8: 12 | L8: 31 | M8: 37 | N8: SWEDEN | O8: #VALUE! | P8: Victor Eklund (LW) | Q8: 38993 | R8: 5'11" | S8: 161 | T8: R
A9: 2025 | C9: Caleb Desnoyers | D9: 8 | E9: F | F9: Moncton Wildcats | G9: QMJHL | H9: =VLOOKUP(G9, Sheet3!$A$2:$B$40, 2, FALSE) -> 0.27 | I9: 56 | J9: 35 | K9: 49 | L9: 84 | M9: 39 | N9: CANADA | O9: #VALUE! | P9: Caleb Desnoyers (C) | Q9: 39183 | R9: 6'2" | S9: 172 | T9: L
A10: 2025 | C10: Jackson Smith | D10: =VLOOKUP(C10, Rankings!$A$2:$B$101, 2, FALSE) -> 9 | E10: D | F10: Tri-City Americans | G10: WHL | H10: =VLOOKUP(G10, Sheet3!$A$2:$B$40, 2, FALSE) -> 0.29 | I10: 68 | J10: 11 | K10: 43 | L10: 54 | M10: 48 | N10: CANADA | O10: #VALUE! | P10: Jackson Smith (D) | Q10: 39215 | R10: 6'3" | S10: 190 | T10: L
A11: 2025 | C11: Jake O'Brien | D11: =VLOOKUP(C11, Rankings!$A$2:$B$101, 2, FALSE) -> 10 | E11: F | F11: Brantford Bulldogs | G11: OHL | H11: =VLOOKUP(G11, Sheet3!$A$2:$B$40, 2, FALSE) -> 0.3 | I11: 66 | J11: 32 | K11: 66 | L11: 98 | M11: 18 | N11: CANADA | O11: #VALUE! | P11: Jake O'Brien (C) | Q11: 39249 | R11: 6'2" | S11: 170 | T11: R
A12: 2025 | C12: Radim Mrtka | D12: =VLOOKUP(C12, Rankings!$A$2:$B$101, 2, FALSE) -> 11 | E12: D | F12: Seattle Thunderbirds | G12: WHL | H12: =VLOOKUP(G12, Sheet3!$A$2:$B$40, 2, FALSE) -> 0.29 | I12: 43 | J12: 3 | K12: 32 | L12: 35 | M12: 46 | N12: CZECHIA | O12: #VALUE! | P12: Radim Mrtka (D) | Q12: 39242 | R12: 6'6" | S12: 216 | T12: R
A13: 2025 | C13: Carter Bear | D13: =VLOOKUP(C13, Rankings!$A$2:$B$101, 2, FALSE) -> 12 | E13: F | F13: Everett Silvertips | G13: WHL | H13: =VLOOKUP(G13, Sheet3!$A$2:$B$40, 2, FALSE) -> 0.29 | I13: 56 | J13: 40 | K13: 42 | L13: 82 | M13: 77 | N13: CANADA | O13: #VALUE! | P13: Carter Bear (C/LW) | Q13: 39025 | R13: 6'0" | S13: 176 | T13: L
A14: 2025 | C14: Malcolm Spence | D14: =VLOOKUP(C14, Rankings!$A$2:$B$101, 2, FALSE) -> 13 | E14: F | F14: Erie Otters | G14: OHL | H14: =VLOOKUP(G14, Sheet3!$A$2:$B$40, 2, FALSE) -> 0.3 | I14: 65 | J14: 32 | K14: 41 | L14: 73 | M14: 57 | N14: CANADA | O14: #VALUE! | P14: Malcolm Spence (LW) | Q14: 38982 | R14: 6'2" | S14: 201 | T14: L
A15: 2025 | C15: Lynden Lakovic | D15: 14 | E15: F | F15: Moose Jaw Warriors | G15: WHL | H15: =VLOOKUP(G15, Sheet3!$A$2:$B$40, 2, FALSE) -> 0.29 | I15: 47 | J15: 27 | K15: 31 | L15: 58 | M15: 4 | N15: CANADA | O15: #VALUE! | P15: Lynden Lakovic (F) | Q15: 39063 | R15: 6'4" | S15: 190 | T15: L
A16: 2025 | C16: Brady Martin | D16: =VLOOKUP(C16, Rankings!$A$2:$B$101, 2, FALSE) -> 15 | E16: F | F16: Soo Greyhounds | G16: OHL | H16: =VLOOKUP(G16, Sheet3!$A$2:$B$40, 2, FALSE) -> 0.3 | I16: 57 | J16: 33 | K16: 39 | L16: 72 | M16: 68 | N16: CANADA | O16: #VALUE! | P16: Brady Martin (C) | Q16: 39157 | R16: 6'0" | S16: 174 | T16: R
A17: 2025 | C17: Justin Carbonneau | D17: =VLOOKUP(C17, Rankings!$A$2:$B$101, 2, FALSE) -> 16 | E17: F | F17: Blainville-Boisbriand Armada | G17: QMJHL | H17: =VLOOKUP(G17, Sheet3!$A$2:$B$40, 2, FALSE) -> 0.27 | I17: 62 | J17: 46 | K17: 43 | L17: 89 | M17: 61 | N17: CANADA | O17: #VALUE! | P17: Justin Carbonneau (RW) | Q17: 39046 | R17: 6'1" | S17: 192 | T17: R
A18: 2025 | C18: Cullen Potter | D18: =VLOOKUP(C18, Rankings!$A$2:$B$101, 2, FALSE) -> 17 | E18: F | F18: Arizona State Univ. | G18: NCAA | H18: =VLOOKUP(G18, Sheet3!$A$2:$B$40, 2, FALSE) -> 0.32 | I18: 35 | J18: 13 | K18: 9 | L18: 22 | M18: 6 | N18: USA | O18: #VALUE! | P18: Cullen Potter (LW) | Q18: 39092 | R18: 5'10" | S18: 172 | T18: L
A19: 2025 | C19: Logan Hensler | D19: =VLOOKUP(C19, Rankings!$A$2:$B$101, 2, FALSE) -> 18 | E19: D | F19: Univ. of Wisconsin | G19: NCAA | H19: =VLOOKUP(G19, Sheet3!$A$2:$B$40, 2, FALSE) -> 0.32 | I19: 32 | J19: 2 | K19: 10 | L19: 12 | M19: 27 | N19: USA | O19: #VALUE! | P19: Logan Hensler (D) | Q19: 39004 | R19: 6'2" | S19: 196 | T19: R
A20: 2025 | C20: Benjamin Kindel | D20: =VLOOKUP(C20, Rankings!$A$2:$B$101, 2, FALSE) -> 19 | E20: F | F20: Calgary Hitmen | G20: WHL | H20: =VLOOKUP(G20, Sheet3!$A$2:$B$40, 2, FALSE) -> 0.29 | I20: 65 | J20: 35 | K20: 64 | L20: 99 | M20: 39 | N20: CANADA | O20: #VALUE! | P20: Benjamin Kindel (RW) | Q20: 39191 | R20: 5'10" | S20: 176 | T20: R
A21: 2025 | C21: Cameron Reid | D21: =VLOOKUP(C21, Rankings!$A$2:$B$101, 2, FALSE) -> 20 | E21: D | F21: Kitchener Rangers | G21: OHL | H21: =VLOOKUP(G21, Sheet3!$A$2:$B$40, 2, FALSE) -> 0.3 | I21: 67 | J21: 14 | K21: 40 | L21: 54 | M21: 44 | N21: CANADA | O21: #VALUE! | P21: Cameron Reid (D) | Q21: 39180 | R21: 6'0" | S21: 174 | T21: L
A22: 2025 | C22: Braeden Cootes | D22: =VLOOKUP(C22, Rankings!$A$2:$B$101, 2, FALSE) -> 21 | E22: F | F22: Seattle Thunderbirds | G22: WHL | H22: =VLOOKUP(G22, Sheet3!$A$2:$B$40, 2, FALSE) -> 0.29 | I22: 60 | J22: 26 | K22: 37 | L22: 63 | M22: 18 | N22: CANADA | O22: #VALUE! | P22: Braeden Cootes (C) | Q22: 39122 | R22: 6'0" | S22: 183 | T22: R
A23: 2025 | C23: Cole Reschny | D23: =VLOOKUP(C23, Rankings!$A$2:$B$101, 2, FALSE) -> 22 | E23: F | F23: Victoria Royals | G23: WHL | H23: =VLOOKUP(G23, Sheet3!$A$2:$B$40, 2, FALSE) -> 0.29 | I23: 62 | J23: 26 | K23: 66 | L23: 92 | M23: 44 | N23: CANADA | O23: #VALUE! | P23: Cole Reschny (F) | Q23: 39178 | R23: 5'10" | S23: 187 | T23: L
A24: 2025 | C24: Bill Zonnon | D24: =VLOOKUP(C24, Rankings!$A$2:$B$101, 2, FALSE) -> 23 | E24: F | F24: Rouyn-Noranda Huskies | G24: QMJHL | H24: =VLOOKUP(G24, Sheet3!$A$2:$B$40, 2, FALSE) -> 0.27 | I24: 64 | J24: 28 | K24: 55 | L24: 83 | M24: 32 | N24: CANADA | O24: #VALUE! | P24: Bill Zonnon (LW) | Q24: 38993 | R24: 6'2" | S24: 190 | T24: L
A25: 2025 | C25: Kashawn Aitcheson | D25: =VLOOKUP(C25, Rankings!$A$2:$B$101, 2, FALSE) -> 24 | E25: D | F25: Barrie Colts | G25: OHL | H25: =VLOOKUP(G25, Sheet3!$A$2:$B$40, 2, FALSE) -> 0.3 | I25: 64 | J25: 26 | K25: 33 | L25: 59 | M25: 88 | N25: CANADA | O25: #VALUE! | P25: Kashawn Aitcheson (D) | Q25: 38981 | R25: 6'1" | S25: 198 | T25: L
A26: 2025 | C26: Cameron Schmidt | D26: =VLOOKUP(C26, Rankings!$A$2:$B$101, 2, FALSE) -> 25 | E26: F | F26: Vancouver Giants | G26: WHL | H26: =VLOOKUP(G26, Sheet3!$A$2:$B$40, 2, FALSE) -> 0.29 | I26: 61 | J26: 40 | K26: 38 | L26: 78 | M26: 44 | N26: CANADA | O26: #VALUE! | P26: Cameron Schmidt (RW) | Q26: 39101 | R26: 5'7" | S26: 157 | T26: R
A27: 2025 | C27: Milton Gastrin | D27: 26 | E27: F | F27: MoDo Hockey J20 | G27: J20 Nationell | H27: =VLOOKUP(G27, Sheet3!$A$2:$B$40, 2, FALSE) -> 0.27 | I27: 40 | J27: 18 | K27: 24 | L27: 42 | M27: 18 | N27: SWEDEN | O27: #VALUE! | P27: Milton Gästrin (C/LW) | Q27: 39235 | R27: 6'1" | S27: 185 | T27: L
A28: 2025 | C28: Blake Fiddler | D28: =VLOOKUP(C28, Rankings!$A$2:$B$101, 2, FALSE) -> 27 | E28: D | F28: Edmonton Oil Kings | G28: WHL | H28: =VLOOKUP(G28, Sheet3!$A$2:$B$40, 2, FALSE) -> 0.29 | I28: 64 | J28: 10 | K28: 23 | L28: 33 | M28: 36 | N28: USA | O28: #VALUE! | P28: Blake Fiddler (D) | Q28: 39272 | R28: 6'4" | S28: 209 | T28: R
A29: 2025 | C29: Sascha Boumedienne | D29: =VLOOKUP(C29, Rankings!$A$2:$B$101, 2, FALSE) -> 28 | E29: D | F29: Boston Univ. | G29: NCAA | H29: =VLOOKUP(G29, Sheet3!$A$2:$B$40, 2, FALSE) -> 0.32 | I29: 40 | J29: 3 | K29: 10 | L29: 13 | M29: 33 | N29: SWEDEN | O29: #VALUE! | P29: Sascha Boumedienne (D) | Q29: 39099 | R29: 6'2" | S29: 183 | T29: L
A30: 2025 | C30: Ivan Ryabkin | D30: 29 | E30: F | F30: Muskegon Lumberjacks | G30: USHL | H30: =VLOOKUP(G30, Sheet3!$A$2:$B$40, 2, FALSE) -> 0.27 | I30: 27 | J30: 19 | K30: 11 | L30: 30 | M30: 70 | N30: RUSSIA | O30: #VALUE! | P30: Ivan Ryabkin (C) | Q30: 39197 | R30: 6'0" | S30: 201 | T30: L
A31: 2025 | C31: William Moore | D31: =VLOOKUP(C31, Rankings!$A$2:$B$101, 2, FALSE) -> 30 | E31: F | F31: U.S. National U18 Team | G31: NTDP | H31: =VLOOKUP(G31, Sheet3!$A$2:$B$40, 2, FALSE) -> 0.28 | I31: 64 | J31: 27 | K31: 32 | L31: 59 | M31: 8 | N31: USA | O31: #VALUE! | P31: William Moore (C) | Q31: 39165 | R31: 6'2" | S31: 174 | T31: L
A32: 2025 | C32: Jack Murtagh | D32: =VLOOKUP(C32, Rankings!$A$2:$B$101, 2, FALSE) -> 31 | E32: F | F32: U.S. National U18 Team | G32: NTDP | H32: =VLOOKUP(G32, Sheet3!$A$2:$B$40, 2, FALSE) -> 0.28 | I32: 56 | J32: 22 | K32: 31 | L32: 53 | M32: 36 | N32: USA | O32: #VALUE! | P32: Jack Murtagh (C/LW) | Q32: 39316 | R32: 6'1" | S32: 198 | T32: L
A33: 2025 | C33: Joshua Ravensbergen | D33: =VLOOKUP(C33, Rankings!$A$2:$B$101, 2, FALSE) -> 32 | E33: G | F33: Prince George Cougars | G33: WHL | H33: =VLOOKUP(G33, Sheet3!$A$2:$B$40, 2, FALSE) -> 0.29 | I33: 51 | J33: 3 | K33: 0.901 | L33: - | M33: - | N33: CANADA | O33: #VALUE! | P33: Joshua Ravensbergen (G) | Q33: 39048 | R33: 6'5" | S33: 192 | T33: R
A34: 2025 | C34: Jack Nesbitt | D34: =VLOOKUP(C34, Rankings!$A$2:$B$101, 2, FALSE) -> 33 | E34: F | F34: Windsor Spitfires | G34: OHL | H34: =VLOOKUP(G34, Sheet3!$A$2:$B$40, 2, FALSE) -> 0.3 | I34: 65 | J34: 25 | K34: 39 | L34: 64 | M34: 74 | N34: CANADA | O34: #VALUE! | P34: Jack Nesbitt (C) | Q34: 39094 | R34: 6'4" | S34: 183 | T34: L
A35: 2025 | C35: Shane Vansaghi | D35: =VLOOKUP(C35, Rankings!$A$2:$B$101, 2, FALSE) -> 34 | E35: F | F35: Michigan State Univ. | G35: NCAA | H35: =VLOOKUP(G35, Sheet3!$A$2:$B$40, 2, FALSE) -> 0.32 | I35: 37 | J35: 6 | K35: 10 | L35: 16 | M35: 30 | N35: USA | O35: #VALUE! | P35: Shane Vansaghi (RW) | Q35: 39001 | R35: 6'2" | S35: 216 | T35: R
A36: 2025 | C36: Cole McKinney | D36: =VLOOKUP(C36, Rankings!$A$2:$B$101, 2, FALSE) -> 35 | E36: F | F36: U.S. National U18 Team | G36: NTDP | H36: =VLOOKUP(G36, Sheet3!$A$2:$B$40, 2, FALSE) -> 0.28 | I36: 60 | J36: 27 | K36: 34 | L36: 61 | M36: 61 | N36: USA | O36: #VALUE! | P36: Cole McKinney (C) | Q36: 39157 | R36: 6'0" | S36: 198 | T36: R
A37: 2025 | C37: Jakob Ihs-Wozniak | D37: =VLOOKUP(C37, Rankings!$A$2:$B$101, 2, FALSE) -> 36 | E37: F | F37: LuleÃ¥ HF J20 | G37: J20 Nationell | H37: =VLOOKUP(G37, Sheet3!$A$2:$B$40, 2, FALSE) -> 0.27 | I37: 40 | J37: 23 | K37: 34 | L37: 57 | M37: 18 | N37: SWEDEN | O37: #VALUE! | P37: Jakob Ihs-Wozniak (RW) | Q37: 39114 | R37: 6'3" | S37: 185 | T37: R
A38: 2025 | C38: Eric Nilson | D38: =VLOOKUP(C38, Rankings!$A$2:$B$101, 2, FALSE) -> 37 | E38: F | F38: DjurgÃ¥rdens IF J20 | G38: J20 Nationell | H38: =VLOOKUP(G38, Sheet3!$A$2:$B$40, 2, FALSE) -> 0.27 | I38: 37 | J38: 12 | K38: 26 | L38: 38 | M38: 56 | N38: SWEDEN | O38: #VALUE! | P38: Eric Nilson (C) | Q38: 39213 | R38: 6'0" | S38: 154 | T38: R
A39: 2025 | C39: Ryker Lee | D39: 38 | E39: F | F39: Madison Capitols | G39: USHL | H39: =VLOOKUP(G39, Sheet3!$A$2:$B$40, 2, FALSE) -> 0.27 | I39: 58 | J39: 31 | K39: 37 | L39: 68 | M39: 18 | N39: USA | O39: #VALUE! | P39: Ryker Lee (F) | Q39: 39029 | R39: 6'0" | S39: 181 | T39: R
A40: 2025 | C40: Benjamin Kevan | D40: =VLOOKUP(C40, Rankings!$A$2:$B$101, 2, FALSE) -> 39 | E40: F | F40: Des Moines Buccaneers | G40: USHL | H40: =VLOOKUP(G40, Sheet3!$A$2:$B$40, 2, FALSE) -> 0.27 | I40: 51 | J40: 13 | K40: 30 | L40: 43 | M40: 43 | N40: USA | O40: #VALUE! | P40: Benjamin Kevan (F) | Q40: 39085 | R40: 6'0" | S40: 183 | T40: R
...

Sheet Pivot_Table
A3: Row Labels | B3: Count of NATIONALITY
A4: CANADA | B4: 40
A5: CHINA | B5: 1
A6: CZECHIA | B6: 6
A7: FINLAND | B7: 2
A8: GERMANY | B8: 1
A9: LATVIA | B9: 1
A10: RUSSIA | B10: 8
A11: SLOVAKIA | B11: 5
A12: SWEDEN | B12: 14
A13: SWITZERLAND | B13: 1
A14: USA | B14: 21
A15: Grand Total | B15: 100

Sheet Sheet10
A1: Country | B1: Total
A2: CANADA | B2: 40
A3: CHINA | B3: 1
A4: CZECHIA | B4: 6
A5: FINLAND | B5: 2
A6: GERMANY | B6: 1
A7: LATVIA | B7: 1
A8: RUSSIA | B8: 8
A9: SLOVAKIA | B9: 5
A10: SWEDEN | B10: 14
A11: SWITZERLAND | B11: 1

Sheet league_and_position
A1: League | B1: Count | M1: Position | N1: Count
A2: OHL | B2: 23 | M2: F | N2: 66
A3: WHL | B3: 17 | M3: D | N3: 28
A4: J20 Nationell | B4: 11 | M4: G | N4: 6
A5: USHL | B5: 10
A6: NTDP | B6: 8
A7: QMJHL | B7: 8
A8: MHL | B8: 6
A9: NCAA | B9: 6
A10: HockeyAllsvenskan | B10: 3
A11: U20 SM-sarja | B11: 3
A12: Czechia | B12: 1
A13: Liiga | B13: 1
A14: SHL | B14: 1
A15: Slovakia | B15: 1
A16: USHS-MN | B16: 1

Sheet top_10
A1: NATIONALITY | B1: COUNT | C1: RELATIVE | F1: NATIONALITY | G1: RELATIVE | I1: PLAYER | J1: RANKING | K1: POSITION | L1: LEAGUE | M1: NATIONALITY | N1: FLAG
A2: CANADA | B2: 40 | C2: =B2/B13 -> 0.4 | F2: CANADA | G2: 0.4 | I2: Matthew Schaefer | J2: 1 | K2: D | L2: OHL | M2: CANADA | N2: #VALUE!
A3: CHINA | B3: 1 | C3: =B3/B13 -> 0.01 | F3: USA | G3: 0.21 | I3: Michael Misa | J3: 2 | K3: F | L3: OHL | M3: CANADA | N3: #VALUE!
A4: CZECHIA | B4: 6 | C4: =B4/B13 -> 0.06 | F4: SWEDEN | G4: 0.14 | I4: James Hagens | J4: 3 | K4: F | L4: NCAA | M4: USA | N4: #VALUE!
A5: FINLAND | B5: 2 | C5: =B5/B13 -> 0.02 | F5: RUSSIA | G5: 0.08 | I5: Porter Martone | J5: 4 | K5: F | L5: OHL | M5: CANADA | N5: #VALUE!
A6: GERMANY | B6: 1 | C6: =B6/B13 -> 0.01 | F6: CZECHIA | G6: 0.06 | I6: Anton Frondell | J6: 5 | K6: F | L6: HockeyAllsvenskan | M6: SWEDEN | N6: #VALUE!
A7: LATVIA | B7: 1 | C7: =B7/B13 -> 0.01 | F7: SLOVAKIA | G7: 0.05 | I7: Roger McQueen | J7: 6 | K7: F | L7: WHL | M7: CANADA | N7: #VALUE!
A8: RUSSIA | B8: 8 | C8: =B8/B13 -> 0.08 | F8: FINLAND | G8: 0.02 | I8: Victor Eklund | J8: 7 | K8: F | L8: HockeyAllsvenskan | M8: SWEDEN | N8: #VALUE!
A9: SLOVAKIA | B9: 5 | C9: =B9/B13 -> 0.05 | F9: CHINA | G9: 0.01 | I9: Caleb Desnoyers | J9: 8 | K9: F | L9: QMJHL | M9: CANADA | N9: #VALUE!
A10: SWEDEN | B10: 14 | C10: =B10/B13 -> 0.14 | F10: GERMANY | G10: 0.01 | I10: Jackson Smith | J10: 9 | K10: D | L10: WHL | M10: CANADA | N10: #VALUE!
A11: SWITZERLAND | B11: 1 | C11: =B11/B13 -> 0.01 | F11: LATVIA | G11: 0.01 | I11: Jake O'Brien | J11: 10 | K11: F | L11: OHL | M11: CANADA | N11: #VALUE!
A12: USA | B12: 21 | C12: =B12/B13 -> 0.21 | F12: SWITZERLAND | G12: 0.01
A13: TOTAL | B13: =SUM(B2:B12) -> 100 | C13: =SUM(C2:C12) -> 1

Sheet top_100_prospects only
A1: YEAR | B1: ROUND | C1: PLAYER | D1: RANKING | E1: POSITION | F1: TEAM | G1: LEAGUE | H1: NHL_EQUIVALENT | I1: GP | J1: G | K1: A | L1: PTS | M1: PIM | N1: GPG | O1: APG | P1: PTSPG | Q1: PIMPG | R1: PIMPPTS | S1: PEN_EFFICIENCY | T1: NHLe | U1: GPTSRATIO | V1: APTSRATIO | W1: GAA | X1: S_PCT | Y1: NATIONALITY | Z1: FLAG | AA1: PLAYER_W_POSITION | AB1: BIRTH_DATE | AC1: HEIGHT | AD1: WEIGHT | AE1: SHOOTS
A2: 2025 | C2: Matthew Schaefer | D2: 1 | E2: D | F2: Erie Otters | G2: OHL | H2: 0.3 | I2: 17 | J2: 7 | K2: 15 | L2: 22 | M2: 8 | N2: =Table24[[#This Row],[G]]/Table24[[#This Row],[GP]] -> 0.41176471 | O2: =Table24[[#This Row],[A]]/Table24[[#This Row],[GP]] -> 0.88235294 | P2: =Table24[[#This Row],[PTS]]/Table24[[#This Row],[GP]] -> 1.2941176 | Q2: =Table24[[#This Row],[PIM]]/Table24[[#This Row],[GP]] -> 0.47058824 | R2: =Table24[[#This Row],[PIM]]/Table24[[#This Row],[PTS]] -> 0.36363636 | S2: =Table24[[#This Row],[PTS]]/Table24[[#This Row],[PIM]] -> 2.75 | T2: =Table24[[#This Row],[PTS]]/Table24[[#This Row],[GP]]*Table24[[#This Row],[NHL_EQUIVALENT]] -> 0.38823529 | U2: =Table24[[#This Row],[G]]/Table24[[#This Row],[PTS]] -> 0.31818182 | V2: =Table24[[#This Row],[A]]/Table24[[#This Row],[PTS]] -> 0.68181818 | W2: 0 | X2: 0 | Y2: CANADA | Z2: #VALUE! | AA2: Matthew Schaefer (D) | AB2: 39330 | AC2: 6'2" | AD2: 183 | AE2: L
A3: 2025 | C3: Michael Misa | D3: 2 | E3: F | F3: Saginaw Spirit | G3: OHL | H3: 0.3 | I3: 65 | J3: 62 | K3: 72 | L3: 134 | M3: 45 | N3: =Table24[[#This Row],[G]]/Table24[[#This Row],[GP]] -> 0.95384615 | O3: =Table24[[#This Row],[A]]/Table24[[#This Row],[GP]] -> 1.1076923 | P3: =Table24[[#This Row],[PTS]]/Table24[[#This Row],[GP]] -> 2.0615385 | Q3: =Table24[[#This Row],[PIM]]/Table24[[#This Row],[GP]] -> 0.69230769 | R3: =Table24[[#This Row],[PIM]]/Table24[[#This Row],[PTS]] -> 0.3358209 | S3: =Table24[[#This Row],[PTS]]/Table24[[#This Row],[PIM]] -> 2.9777778 | T3: =Table24[[#This Row],[PTS]]/Table24[[#This Row],[GP]]*Table24[[#This Row],[NHL_EQUIVALENT]] -> 0.61846154 | U3: =Table24[[#This Row],[G]]/Table24[[#This Row],[PTS]] -> 0.46268657 | V3: =Table24[[#This Row],[A]]/Table24[[#This Row],[PTS]] -> 0.53731343 | W3: 0 | X3: 0 | Y3: CANADA | Z3: #VALUE! | AA3: Michael Misa (C/LW) | AB3: 39129 | AC3: 6'1" | AD3: 185 | AE3: L
A4: 2025 | C4: James Hagens | D4: 3 | E4: F | F4: Boston College | G4: NCAA | H4: 0.32 | I4: 37 | J4: 11 | K4: 26 | L4: 37 | M4: 24 | N4: =Table24[[#This Row],[G]]/Table24[[#This Row],[GP]] -> 0.2972973 | O4: =Table24[[#This Row],[A]]/Table24[[#This Row],[GP]] -> 0.7027027 | P4: =Table24[[#This Row],[PTS]]/Table24[[#This Row],[GP]] -> 1 | Q4: =Table24[[#This Row],[PIM]]/Table24[[#This Row],[GP]] -> 0.64864865 | R4: =Table24[[#This Row],[PIM]]/Table24[[#This Row],[PTS]] -> 0.64864865 | S4: =Table24[[#This Row],[PTS]]/Table24[[#This Row],[PIM]] -> 1.5416667 | T4: =Table24[[#This Row],[PTS]]/Table24[[#This Row],[GP]]*Table24[[#This Row],[NHL_EQUIVALENT]] -> 0.32 | U4: =Table24[[#This Row],[G]]/Table24[[#This Row],[PTS]] -> 0.2972973 | V4: =Table24[[#This Row],[A]]/Table24[[#This Row],[PTS]] -> 0.7027027 | W4: 0 | X4: 0 | Y4: USA | Z4: #VALUE! | AA4: James Hagens (C) | AB4: 39024 | AC4: 5'11" | AD4: 176 | AE4: L
A5: 2025 | C5: Porter Martone | D5: 4 | E5: F | F5: Brampton Steelheads | G5: OHL | H5: 0.3 | I5: 57 | J5: 37 | K5: 61 | L5: 98 | M5: 74 | N5: =Table24[[#This Row],[G]]/Table24[[#This Row],[GP]] -> 0.64912281 | O5: =Table24[[#This Row],[A]]/Table24[[#This Row],[GP]] -> 1.0701754 | P5: =Table24[[#This Row],[PTS]]/Table24[[#This Row],[GP]] -> 1.7192982 | Q5: =Table24[[#This Row],[PIM]]/Table24[[#This Row],[GP]] -> 1.2982456 | R5: =Table24[[#This Row],[PIM]]/Table24[[#This Row],[PTS]] -> 0.75510204 | S5: =Table24[[#This Row],[PTS]]/Table24[[#This Row],[PIM]] -> 1.3243243 | T5: =Table24[[#This Row],[PTS]]/Table24[[#This Row],[GP]]*Table24[[#This Row],[NHL_EQUIVALENT]] -> 0.51578947 | U5: =Table24[[#This Row],[G]]/Table24[[#This Row],[PTS]] -> 0.37755102 | V5: =Table24[[#This Row],[A]]/Table24[[#This Row],[PTS]] -> 0.62244898 | W5: 0 | X5: 0 | Y5: CANADA | Z5: #VALUE! | AA5: Porter Martone (RW) | AB5: 39016 | AC5: 6'3" | AD5: 207 | AE5: R
A6: 2025 | C6: Anton Frondell | D6: 5 | E6: F | F6: Djurgardens IF | G6: HockeyAllsvenskan | H6: 0.41 | I6: 29 | J6: 11 | K6: 14 | L6: 25 | M6: 16 | N6: =Table24[[#This Row],[G]]/Table24[[#This Row],[GP]] -> 0.37931034 | O6: =Table24[[#This Row],[A]]/Table24[[#This Row],[GP]] -> 0.48275862 | P6: =Table24[[#This Row],[PTS]]/Table24[[#This Row],[GP]] -> 0.86206897 | Q6: =Table24[[#This Row],[PIM]]/Table24[[#This Row],[GP]] -> 0.55172414 | R6: =Table24[[#This Row],[PIM]]/Table24[[#This Row],[PTS]] -> 0.64 | S6: =Table24[[#This Row],[PTS]]/Table24[[#This Row],[PIM]] -> 1.5625 | T6: =Table24[[#This Row],[PTS]]/Table24[[#This Row],[GP]]*Table24[[#This Row],[NHL_EQUIVALENT]] -> 0.35344828 | U6: =Table24[[#This Row],[G]]/Table24[[#This Row],[PTS]] -> 0.44 | V6: =Table24[[#This Row],[A]]/Table24[[#This Row],[PTS]] -> 0.56 | W6: 0 | X6: 0 | Y6: SWEDEN | Z6: #VALUE! | AA6: Anton Frondell (C) | AB6: 39209 | AC6: 6'0" | AD6: 196 | AE6: L
A7: 2025 | C7: Roger McQueen | D7: 6 | E7: F | F7: Brandon Wheat Kings | G7: WHL | H7: 0.29 | I7: 17 | J7: 10 | K7: 10 | L7: 20 | M7: 40 | N7: =Table24[[#This Row],[G]]/Table24[[#This Row],[GP]] -> 0.58823529 | O7: =Table24[[#This Row],[A]]/Table24[[#This Row],[GP]] -> 0.58823529 | P7: =Table24[[#This Row],[PTS]]/Table24[[#This Row],[GP]] -> 1.1764706 | Q7: =Table24[[#This Row],[PIM]]/Table24[[#This Row],[GP]] -> 2.3529412 | R7: =Table24[[#This Row],[PIM]]/Table24[[#This Row],[PTS]] -> 2 | S7: =Table24[[#This Row],[PTS]]/Table24[[#This Row],[PIM]] -> 0.5 | T7: =Table24[[#This Row],[PTS]]/Table24[[#This Row],[GP]]*Table24[[#This Row],[NHL_EQUIVALENT]] -> 0.34117647 | U7: =Table24[[#This Row],[G]]/Table24[[#This Row],[PTS]] -> 0.5 | V7: =Table24[[#This Row],[A]]/Table24[[#This Row],[PTS]] -> 0.5 | W7: 0 | X7: 0 | Y7: CANADA | Z7: #VALUE! | AA7: Roger McQueen (F) | AB7: 38992 | AC7: 6'5" | AD7: 192 | AE7: R
A8: 2025 | C8: Victor Eklund | D8: 7 | E8: F | F8: Djurgardens IF | G8: HockeyAllsvenskan | H8: 0.41 | I8: 42 | J8: 19 | K8: 12 | L8: 31 | M8: 37 | N8: =Table24[[#This Row],[G]]/Table24[[#This Row],[GP]] -> 0.45238095 | O8: =Table24[[#This Row],[A]]/Table24[[#This Row],[GP]] -> 0.28571429 | P8: =Table24[[#This Row],[PTS]]/Table24[[#This Row],[GP]] -> 0.73809524 | Q8: =Table24[[#This Row],[PIM]]/Table24[[#This Row],[GP]] -> 0.88095238 | R8: =Table24[[#This Row],[PIM]]/Table24[[#This Row],[PTS]] -> 1.1935484 | S8: =Table24[[#This Row],[PTS]]/Table24[[#This Row],[PIM]] -> 0.83783784 | T8: =Table24[[#This Row],[PTS]]/Table24[[#This Row],[GP]]*Table24[[#This Row],[NHL_EQUIVALENT]] -> 0.30261905 | U8: =Table24[[#This Row],[G]]/Table24[[#This Row],[PTS]] -> 0.61290323 | V8: =Table24[[#This Row],[A]]/Table24[[#This Row],[PTS]] -> 0.38709677 | W8: 0 | X8: 0 | Y8: SWEDEN | Z8: #VALUE! | AA8: Victor Eklund (LW) | AB8: 38993 | AC8: 5'11" | AD8: 161 | AE8: R
A9: 2025 | C9: Caleb Desnoyers | D9: 8 | E9: F | F9: Moncton Wildcats | G9: QMJHL | H9: 0.27 | I9: 56 | J9: 35 | K9: 49 | L9: 84 | M9: 39 | N9: =Table24[[#This Row],[G]]/Table24[[#This Row],[GP]] -> 0.625 | O9: =Table24[[#This Row],[A]]/Table24[[#This Row],[GP]] -> 0.875 | P9: =Table24[[#This Row],[PTS]]/Table24[[#This Row],[GP]] -> 1.5 | Q9: =Table24[[#This Row],[PIM]]/Table24[[#This Row],[GP]] -> 0.69642857 | R9: =Table24[[#This Row],[PIM]]/Table24[[#This Row],[PTS]] -> 0.46428571 | S9: =Table24[[#This Row],[PTS]]/Table24[[#This Row],[PIM]] -> 2.1538462 | T9: =Table24[[#This Row],[PTS]]/Table24[[#This Row],[GP]]*Table24[[#This Row],[NHL_EQUIVALENT]] -> 0.405 | U9: =Table24[[#This Row],[G]]/Table24[[#This Row],[PTS]] -> 0.41666667 | V9: =Table24[[#This Row],[A]]/Table24[[#This Row],[PTS]] -> 0.58333333 | W9: 0 | X9: 0 | Y9: CANADA | Z9: #VALUE! | AA9: Caleb Desnoyers (C) | AB9: 39183 | AC9: 6'2" | AD9: 172 | AE9: L
A10: 2025 | C10: Jackson Smith | D10: 9 | E10: D | F10: Tri-City Americans | G10: WHL | H10: 0.29 | I10: 68 | J10: 11 | K10: 43 | L10: 54 | M10: 48 | N10: =Table24[[#This Row],[G]]/Table24[[#This Row],[GP]] -> 0.16176471 | O10: =Table24[[#This Row],[A]]/Table24[[#This Row],[GP]] -> 0.63235294 | P10: =Table24[[#This Row],[PTS]]/Table24[[#This Row],[GP]] -> 0.79411765 | Q10: =Table24[[#This Row],[PIM]]/Table24[[#This Row],[GP]] -> 0.70588235 | R10: =Table24[[#This Row],[PIM]]/Table24[[#This Row],[PTS]] -> 0.88888889 | S10: =Table24[[#This Row],[PTS]]/Table24[[#This Row],[PIM]] -> 1.125 | T10: =Table24[[#This Row],[PTS]]/Table24[[#This Row],[GP]]*Table24[[#This Row],[NHL_EQUIVALENT]] -> 0.23029412 | U10: =Table24[[#This Row],[G]]/Table24[[#This Row],[PTS]] -> 0.2037037 | V10: =Table24[[#This Row],[A]]/Table24[[#This Row],[PTS]] -> 0.7962963 | W10: 0 | X10: 0 | Y10: CANADA | Z10: #VALUE! | AA10: Jackson Smith (D) | AB10: 39215 | AC10: 6'3" | AD10: 190 | AE10: L
A11: 2025 | C11: Jake O'Brien | D11: 10 | E11: F | F11: Brantford Bulldogs | G11: OHL | H11: 0.3 | I11: 66 | J11: 32 | K11: 66 | L11: 98 | M11: 18 | N11: =Table24[[#This Row],[G]]/Table24[[#This Row],[GP]] -> 0.48484848 | O11: =Table24[[#This Row],[A]]/Table24[[#This Row],[GP]] -> 1 | P11: =Table24[[#This Row],[PTS]]/Table24[[#This Row],[GP]] -> 1.4848485 | Q11: =Table24[[#This Row],[PIM]]/Table24[[#This Row],[GP]] -> 0.27272727 | R11: =Table24[[#This Row],[PIM]]/Table24[[#This Row],[PTS]] -> 0.18367347 | S11: =Table24[[#This Row],[PTS]]/Table24[[#This Row],[PIM]] -> 5.4444444 | T11: =Table24[[#This Row],[PTS]]/Table24[[#This Row],[GP]]*Table24[[#This Row],[NHL_EQUIVALENT]] -> 0.44545455 | U11: =Table24[[#This Row],[G]]/Table24[[#This Row],[PTS]] -> 0.32653061 | V11: =Table24[[#This Row],[A]]/Table24[[#This Row],[PTS]] -> 0.67346939 | W11: 0 | X11: 0 | Y11: CANADA | Z11: #VALUE! | AA11: Jake O'Brien (C) | AB11: 39249 | AC11: 6'2" | AD11: 170 | AE11: R
A12: 2025 | C12: Radim Mrtka | D12: 11 | E12: D | F12: Seattle Thunderbirds | G12: WHL | H12: 0.29 | I12: 43 | J12: 3 | K12: 32 | L12: 35 | M12: 46 | N12: =Table24[[#This Row],[G]]/Table24[[#This Row],[GP]] -> 0.069767442 | O12: =Table24[[#This Row],[A]]/Table24[[#This Row],[GP]] -> 0.74418605 | P12: =Table24[[#This Row],[PTS]]/Table24[[#This Row],[GP]] -> 0.81395349 | Q12: =Table24[[#This Row],[PIM]]/Table24[[#This Row],[GP]] -> 1.0697674 | R12: =Table24[[#This Row],[PIM]]/Table24[[#This Row],[PTS]] -> 1.3142857 | S12: =Table24[[#This Row],[PTS]]/Table24[[#This Row],[PIM]] -> 0.76086957 | T12: =Table24[[#This Row],[PTS]]/Table24[[#This Row],[GP]]*Table24[[#This Row],[NHL_EQUIVALENT]] -> 0.23604651 | U12: =Table24[[#This Row],[G]]/Table24[[#This Row],[PTS]] -> 0.085714286 | V12: =Table24[[#This Row],[A]]/Table24[[#This Row],[PTS]] -> 0.91428571 | W12: 0 | X12: 0 | Y12: CZECHIA | Z12: #VALUE! | AA12: Radim Mrtka (D) | AB12: 39242 | AC12: 6'6" | AD12: 216 | AE12: R
A13: 2025 | C13: Carter Bear | D13: 12 | E13: F | F13: Everett Silvertips | G13: WHL | H13: 0.29 | I13: 56 | J13: 40 | K13: 42 | L13: 82 | M13: 77 | N13: =Table24[[#This Row],[G]]/Table24[[#This Row],[GP]] -> 0.71428571 | O13: =Table24[[#This Row],[A]]/Table24[[#This Row],[GP]] -> 0.75 | P13: =Table24[[#This Row],[PTS]]/Table24[[#This Row],[GP]] -> 1.4642857 | Q13: =Table24[[#This Row],[PIM]]/Table24[[#This Row],[GP]] -> 1.375 | R13: =Table24[[#This Row],[PIM]]/Table24[[#This Row],[PTS]] -> 0.93902439 | S13: =Table24[[#This Row],[PTS]]/Table24[[#This Row],[PIM]] -> 1.0649351 | T13: =Table24[[#This Row],[PTS]]/Table24[[#This Row],[GP]]*Table24[[#This Row],[NHL_EQUIVALENT]] -> 0.42464286 | U13: =Table24[[#This Row],[G]]/Table24[[#This Row],[PTS]] -> 0.48780488 | V13: =Table24[[#This Row],[A]]/Table24[[#This Row],[PTS]] -> 0.51219512 | W13: 0 | X13: 0 | Y13: CANADA | Z13: #VALUE! | AA13: Carter Bear (C/LW) | AB13: 39025 | AC13: 6'0" | AD13: 176 | AE13: L
... A32: 2025 | C32: Jack Murtagh | D32: 31 | E32: F | F32: U.S. National U18 Team | G32: NTDP | H32: 0.28 | I32: 56 | J32: 22 | K32: 31 | L32: 53 | M32: 36 | N32: =Table24[[#This Row],[G]]/Table24[[#This Row],[GP]] -> 0.39285714 | O32: =Table24[[#This Row],[A]]/Table24[[#This Row],[GP]] -> 0.55357143 | P32: =Table24[[#This Row],[PTS]]/Table24[[#This Row],[GP]] -> 0.94642857 | Q32: =Table24[[#This Row],[PIM]]/Table24[[#This Row],[GP]] -> 0.64285714 | R32: =Table24[[#This Row],[PIM]]/Table24[[#This Row],[PTS]] -> 0.67924528 | S32: =Table24[[#This Row],[PTS]]/Table24[[#This Row],[PIM]] -> 1.4722222 | T32: =Table24[[#This Row],[PTS]]/Table24[[#This Row],[GP]]*Table24[[#This Row],[NHL_EQUIVALENT]] -> 0.265 | U32: =Table24[[#This Row],[G]]/Table24[[#This Row],[PTS]] -> 0.41509434 | V32: =Table24[[#This Row],[A]]/Table24[[#This Row],[PTS]] -> 0.58490566 | W32: 0 | X32: 0 | Y32: USA | Z32: #VALUE! | AA32: Jack Murtagh (C/LW) | AB32: 39316 | AC32: 6'1" | AD32: 198 | AE32: L
A33: 2025 | C33: Joshua Ravensbergen | D33: 32 | E33: G | F33: Prince George Cougars | G33: WHL | H33: 0.29 | I33: 51 | J33: 0 | K33: 0 | L33: 0 | M33: 0 | N33: =Table24[[#This Row],[G]]/Table24[[#This Row],[GP]] -> 0 | O33: =Table24[[#This Row],[A]]/Table24[[#This Row],[GP]] -> 0 | P33: =Table24[[#This Row],[PTS]]/Table24[[#This Row],[GP]] -> 0 | Q33: =Table24[[#This Row],[PIM]]/Table24[[#This Row],[GP]] -> 0 | R33: 0 | S33: 0 | T33: =Table24[[#This Row],[PTS]]/Table24[[#This Row],[GP]]*Table24[[#This Row],[NHL_EQUIVALENT]] -> 0 | U33: 0 | V33: 0 | W33: 3 | X33: 0.901 | Y33: CANADA | Z33: #VALUE! | AA33: Joshua Ravensbergen (G) | AB33: 39048 | AC33: 6'5" | AD33: 192 | AE33: R
A34: 2025 | C34: Jack Nesbitt | D34: 33 | E34: F | F34: Windsor Spitfires | G34: OHL | H34: 0.3 | I34: 65 | J34: 25 | K34: 39 | L34: 64 | M34: 74 | N34: =Table24[[#This Row],[G]]/Table24[[#This Row],[GP]] -> 0.38461538 | O34: =Table24[[#This Row],[A]]/Table24[[#This Row],[GP]] -> 0.6 | P34: =Table24[[#This Row],[PTS]]/Table24[[#This Row],[GP]] -> 0.98461538 | Q34: =Table24[[#This Row],[PIM]]/Table24[[#This Row],[GP]] -> 1.1384615 | R34: =Table24[[#This Row],[PIM]]/Table24[[#This Row],[PTS]] -> 1.15625 | S34: =Table24[[#This Row],[PTS]]/Table24[[#This Row],[PIM]] -> 0.86486486 | T34: =Table24[[#This Row],[PTS]]/Table24[[#This Row],[GP]]*Table24[[#This Row],[NHL_EQUIVALENT]] -> 0.29538462 | U34: =Table24[[#This Row],[G]]/Table24[[#This Row],[PTS]] -> 0.390625 | V34: =Table24[[#This Row],[A]]/Table24[[#This Row],[PTS]] -> 0.609375 | W34: 0 | X34: 0 | Y34: CANADA | Z34: #VALUE! | AA34: Jack Nesbitt (C) | AB34: 39094 | AC34: 6'4" | AD34: 183 | AE34: L
A35: 2025 | C35: Shane Vansaghi | D35: 34 | E35: F | F35: Michigan State Univ. | G35: NCAA | H35: 0.32 | I35: 37 | J35: 6 | K35: 10 | L35: 16 | M35: 30 | N35: =Table24[[#This Row],[G]]/Table24[[#This Row],[GP]] -> 0.16216216 | O35: =Table24[[#This Row],[A]]/Table24[[#This Row],[GP]] -> 0.27027027 | P35: =Table24[[#This Row],[PTS]]/Table24[[#This Row],[GP]] -> 0.43243243 | Q35: =Table24[[#This Row],[PIM]]/Table24[[#This Row],[GP]] -> 0.81081081 | R35: =Table24[[#This Row],[PIM]]/Table24[[#This Row],[PTS]] -> 1.875 | S35: =Table24[[#This Row],[PTS]]/Table24[[#This Row],[PIM]] -> 0.53333333 | T35: =Table24[[#This Row],[PTS]]/Table24[[#This Row],[GP]]*Table24[[#This Row],[NHL_EQUIVALENT]] -> 0.13837838 | U35: =Table24[[#This Row],[G]]/Table24[[#This Row],[PTS]] -> 0.375 | V35: =Table24[[#This Row],[A]]/Table24[[#This Row],[PTS]] -> 0.625 | W35: 0 | X35: 0 | Y35: USA | Z35: #VALUE! | AA35: Shane Vansaghi (RW) | AB35: 39001 | AC35: 6'2" | AD35: 216 | AE35: R
A36: 2025 | C36: Cole McKinney | D36: 35 | E36: F | F36: U.S. National U18 Team | G36: NTDP | H36: 0.28 | I36: 60 | J36: 27 | K36: 34 | L36: 61 | M36: 61 | N36: =Table24[[#This Row],[G]]/Table24[[#This Row],[GP]] -> 0.45 | O36: =Table24[[#This Row],[A]]/Table24[[#This Row],[GP]] -> 0.56666667 | P36: =Table24[[#This Row],[PTS]]/Table24[[#This Row],[GP]] -> 1.0166667 | Q36: =Table24[[#This Row],[PIM]]/Table24[[#This Row],[GP]] -> 1.0166667 | R36: =Table24[[#This Row],[PIM]]/Table24[[#This Row],[PTS]] -> 1 | S36: =Table24[[#This Row],[PTS]]/Table24[[#This Row],[PIM]] -> 1 | T36: =Table24[[#This Row],[PTS]]/Table24[[#This Row],[GP]]*Table24[[#This Row],[NHL_EQUIVALENT]] -> 0.28466667 | U36: =Table24[[#This Row],[G]]/Table24[[#This Row],[PTS]] -> 0.44262295 | V36: =Table24[[#This Row],[A]]/Table24[[#This Row],[PTS]] -> 0.55737705 | W36: 0 | X36: 0 | Y36: USA | Z36: #VALUE! | AA36: Cole McKinney (C) | AB36: 39157 | AC36: 6'0" | AD36: 198 | AE36: R
A37: 2025 | C37: Jakob Ihs-Wozniak | D37: 36 | E37: F | F37: Lulea HF J20 | G37: J20 Nationell | H37: 0.27 | I37: 40 | J37: 23 | K37: 34 | L37: 57 | M37: 18 | N37: =Table24[[#This Row],[G]]/Table24[[#This Row],[GP]] -> 0.575 | O37: =Table24[[#This Row],[A]]/Table24[[#This Row],[GP]] -> 0.85 | P37: =Table24[[#This Row],[PTS]]/Table24[[#This Row],[GP]] -> 1.425 | Q37: =Table24[[#This Row],[PIM]]/Table24[[#This Row],[GP]] -> 0.45 | R37: =Table24[[#This Row],[PIM]]/Table24[[#This Row],[PTS]] -> 0.31578947 | S37: =Table24[[#This Row],[PTS]]/Table24[[#This Row],[PIM]] -> 3.1666667 | T37: =Table24[[#This Row],[PTS]]/Table24[[#This Row],[GP]]*Table24[[#This Row],[NHL_EQUIVALENT]] -> 0.38475 | U37: =Table24[[#This Row],[G]]/Table24[[#This Row],[PTS]] -> 0.40350877 | V37: =Table24[[#This Row],[A]]/Table24[[#This Row],[PTS]] -> 0.59649123 | W37: 0 | X37: 0 | Y37: SWEDEN | Z37: #VALUE! | AA37: Jakob Ihs-Wozniak (RW) | AB37: 39114 | AC37: 6'3" | AD37: 185 | AE37: R
A38: 2025 | C38: Eric Nilson | D38: 37 | E38: F | F38: Djurgardens IF J20 | G38: J20 Nationell | H38: 0.27 | I38: 37 | J38: 12 | K38: 26 | L38: 38 | M38: 56 | N38: =Table24[[#This Row],[G]]/Table24[[#This Row],[GP]] -> 0.32432432 | O38: =Table24[[#This Row],[A]]/Table24[[#This Row],[GP]] -> 0.7027027 | P38: =Table24[[#This Row],[PTS]]/Table24[[#This Row],[GP]] -> 1.027027 | Q38: =Table24[[#This Row],[PIM]]/Table24[[#This Row],[GP]] -> 1.5135135 | R38: =Table24[[#This Row],[PIM]]/Table24[[#This Row],[PTS]] -> 1.4736842 | S38: =Table24[[#This Row],[PTS]]/Table24[[#This Row],[PIM]] -> 0.67857143 | T38: =Table24[[#This Row],[PTS]]/Table24[[#This Row],[GP]]*Table24[[#This Row],[NHL_EQUIVALENT]] -> 0.2772973 | U38: =Table24[[#This Row],[G]]/Table24[[#This Row],[PTS]] -> 0.31578947 | V38: =Table24[[#This Row],[A]]/Table24[[#This Row],[PTS]] -> 0.68421053 | W38: 0 | X38: 0 | Y38: SWEDEN | Z38: #VALUE! | AA38: Eric Nilson (C) | AB38: 39213 | AC38: 6'0" | AD38: 154 | AE38: R
A39: 2025 | C39: Ryker Lee | D39: 38 | E39: F | F39: Madison Capitols | G39: USHL | H39: 0.27 | I39: 58 | J39: 31 | K39: 37 | L39: 68 | M39: 18 | N39: =Table24[[#This Row],[G]]/Table24[[#This Row],[GP]] -> 0.53448276 | O39: =Table24[[#This Row],[A]]/Table24[[#This Row],[GP]] -> 0.63793103 | P39: =Table24[[#This Row],[PTS]]/Table24[[#This Row],[GP]] -> 1.1724138 | Q39: =Table24[[#This Row],[PIM]]/Table24[[#This Row],[GP]] -> 0.31034483 | R39: =Table24[[#This Row],[PIM]]/Table24[[#This Row],[PTS]] -> 0.26470588 | S39: =Table24[[#This Row],[PTS]]/Table24[[#This Row],[PIM]] -> 3.7777778 | T39: =Table24[[#This Row],[PTS]]/Table24[[#This Row],[GP]]*Table24[[#This Row],[NHL_EQUIVALENT]] -> 0.31655172 | U39: =Table24[[#This Row],[G]]/Table24[[#This Row],[PTS]] -> 0.45588235 | V39: =Table24[[#This Row],[A]]/Table24[[#This Row],[PTS]] -> 0.54411765 | W39: 0 | X39: 0 | Y39: USA | Z39: #VALUE! | AA39: Ryker Lee (F) | AB39: 39029 | AC39: 6'0" | AD39: 181 | AE39: R
A40: 2025 | C40: Benjamin Kevan | D40: 39 | E40: F | F40: Des Moines Buccaneers | G40: USHL | H40: 0.27 | I40: 51 | J40: 13 | K40: 30 | L40: 43 | M40: 43 | N40: =Table24[[#This Row],[G]]/Table24[[#This Row],[GP]] -> 0.25490196 | O40: =Table24[[#This Row],[A]]/Table24[[#This Row],[GP]] -> 0.58823529 | P40: =Table24[[#This Row],[PTS]]/Table24[[#This Row],[GP]] -> 0.84313725 | Q40: =Table24[[#This Row],[PIM]]/Table24[[#This Row],[GP]] -> 0.84313725 | R40: =Table24[[#This Row],[PIM]]/Table24[[#This Row],[PTS]] -> 1 | S40: =Table24[[#This Row],[PTS]]/Table24[[#This Row],[PIM]] -> 1 | T40: =Table24[[#This Row],[PTS]]/Table24[[#This Row],[GP]]*Table24[[#This Row],[NHL_EQUIVALENT]] -> 0.22764706 | U40: =Table24[[#This Row],[G]]/Table24[[#This Row],[PTS]] -> 0.30232558 | V40: =Table24[[#This Row],[A]]/Table24[[#This Row],[PTS]] -> 0.69767442 | W40: 0 | X40: 0 | Y40: USA | Z40: #VALUE! | AA40: Benjamin Kevan (F) | AB40: 39085 | AC40: 6'0" | AD40: 183 | AE40: R
A41: 2025 | C41: Adam Benak | D41: 40 | E41: F | F41: Youngstown Phantoms | G41: USHL | H41: 0.27 | I41: 56 | J41: 17 | K41: 42 | L41: 59 | M41: 36 | N41: =Table24[[#This Row],[G]]/Table24[[#This Row],[GP]] -> 0.30357143 | O41: =Table24[[#This Row],[A]]/Table24[[#This Row],[GP]] -> 0.75 | P41: =Table24[[#This Row],[PTS]]/Table24[[#This Row],[GP]] -> 1.0535714 | Q41: =Table24[[#This Row],[PIM]]/Table24[[#This Row],[GP]] -> 0.64285714 | R41: =Table24[[#This Row],[PIM]]/Table24[[#This Row],[PTS]] -> 0.61016949 | S41: =Table24[[#This Row],[PTS]]/Table24[[#This Row],[PIM]] -> 1.6388889 | T41: =Table24[[#This Row],[PTS]]/Table24[[#This Row],[GP]]*Table24[[#This Row],[NHL_EQUIVALENT]] -> 0.28446429 | U41: =Table24[[#This Row],[G]]/Table24[[#This Row],[PTS]] -> 0.28813559 | V41: =Table24[[#This Row],[A]]/Table24[[#This Row],[PTS]] -> 0.71186441 | W41: 0 | X41: 0 | Y41: CZECHIA | Z41: #VALUE! | AA41: Adam Benák (C) | AB41: 39182 | AC41: 5'7" | AD41: 161 | AE41: L
A42: 2025 | C42: Kurban Limatov | D42: 41 | E42: D | F42: MHK Dynamo Moskva | G42: MHL | H42: 0.2 | I42: 46 | J42: 8 | K42: 15 | L42: 23 | M42: 44 | N42: =Table24[[#This Row],[G]]/Table24[[#This Row],[GP]] -> 0.17391304 | O42: =Table24[[#This Row],[A]]/Table24[[#This Row],[GP]] -> 0.32608696 | P42: =Table24[[#This Row],[PTS]]/Table24[[#This Row],[GP]] -> 0.5 | Q42: =Table24[[#This Row],[PIM]]/Table24[[#This Row],[GP]] -> 0.95652174 | R42: =Table24[[#This Row],[PIM]]/Table24[[#This Row],[PTS]] -> 1.9130435 | S42: =Table24[[#This Row],[PTS]]/Table24[[#This Row],[PIM]] -> 0.52272727 | T42: =Table24[[#This Row],[PTS]]/Table24[[#This Row],[GP]]*Table24[[#This Row],[NHL_EQUIVALENT]] -> 0.1 | U42: =Table24[[#This Row],[G]]/Table24[[#This Row],[PTS]] -> 0.34782609 | V42: =Table24[[#This Row],[A]]/Table24[[#This Row],[PTS]] -> 0.65217391 | W42: 0 | X42: 0 | Y42: RUSSIA | Z42: #VALUE! | AA42: Kurban Limatov (D) | AB42: 39161 | AC42: 6'3" | AD42: 198 | AE42: L
A43: 2025 | C43: Nathan Behm | D43: 42 | E43: F | F43: Kamloops Blazers | G43: WHL | H43: 0.29 | I43: 59 | J43: 31 | K43: 35 | L43: 66 | M43: 12 | N43: =Table24[[#This Row],[G]]/Table24[[#This Row],[GP]] -> 0.52542373 | O43: =Table24[[#This Row],[A]]/Table24[[#This Row],[GP]] -> 0.59322034 | P43: =Table24[[#This Row],[PTS]]/Table24[[#This Row],[GP]] -> 1.1186441 | Q43: =Table24[[#This Row],[PIM]]/Table24[[#This Row],[GP]] -> 0.20338983 | R43: =Table24[[#This Row],[PIM]]/Table24[[#This Row],[PTS]] -> 0.18181818 | S43: =Table24[[#This Row],[PTS]]/Table24[[#This Row],[PIM]] -> 5.5 | T43: =Table24[[#This Row],[PTS]]/Table24[[#This Row],[GP]]*Table24[[#This Row],[NHL_EQUIVALENT]] -> 0.32440678 | U43: =Table24[[#This Row],[G]]/Table24[[#This Row],[PTS]] -> 0.46969697 | V43: =Table24[[#This Row],[A]]/Table24[[#This Row],[PTS]] -> 0.53030303 | W43: 0 | X43: 0 | Y43: CANADA | Z43: #VALUE! | AA43: Nathan Behm (LW/RW) | AB43: 39190 | AC43: 6'2" | AD43: 198 | AE43: R
A44: 2025 | C44: William Horcoff | D44: 43 | E44: F | F44: U.S. National U18 Team | G44: NTDP | H44: 0.28 | I44: 28 | J44: 8 | K44: 6 | L44: 14 | M44: 34 | N44: =Table24[[#This Row],[G]]/Table24[[#This Row],[GP]] -> 0.28571429 | O44: =Table24[[#This Row],[A]]/Table24[[#This Row],[GP]] -> 0.21428571 | P44: =Table24[[#This Row],[PTS]]/Table24[[#This Row],[GP]] -> 0.5 | Q44: =Table24[[#This Row],[PIM]]/Table24[[#This Row],[GP]] -> 1.2142857 | R44: =Table24[[#This Row],[PIM]]/Table24[[#This Row],[PTS]] -> 2.4285714 | S44: =Table24[[#This Row],[PTS]]/Table24[[#This Row],[PIM]] -> 0.41176471 | T44: =Table24[[#This Row],[PTS]]/Table24[[#This Row],[GP]]*Table24[[#This Row],[NHL_EQUIVALENT]] -> 0.14 | U44: =Table24[[#This Row],[G]]/Table24[[#This Row],[PTS]] -> 0.57142857 | V44: =Table24[[#This Row],[A]]/Table24[[#This Row],[PTS]] -> 0.42857143 | W44: 0 | X44: 0 | Y44: USA | Z44: #VALUE! | AA44: William Horcoff (C) | AB44: 39105 | AC44: 6'4" | AD44: 181 | AE44: L
A45: 2025 | C45: Henry Brzustewicz | D45: 44 | E45: D | F45: London Knights | G45: OHL | H45: 0.3 | I45: 67 | J45: 10 | K45: 32 | L45: 42 | M45: 77 | N45: =Table24[[#This Row],[G]]/Table24[[#This Row],[GP]] -> 0.14925373 | O45: =Table24[[#This Row],[A]]/Table24[[#This Row],[GP]] -> 0.47761194 | P45: =Table24[[#This Row],[PTS]]/Table24[[#This Row],[GP]] -> 0.62686567 | Q45: =Table24[[#This Row],[PIM]]/Table24[[#This Row],[GP]] -> 1.1492537 | R45: =Table24[[#This Row],[PIM]]/Table24[[#This Row],[PTS]] -> 1.8333333 | S45: =Table24[[#This Row],[PTS]]/Table24[[#This Row],[PIM]] -> 0.54545455 | T45: =Table24[[#This Row],[PTS]]/Table24[[#This Row],[GP]]*Table24[[#This Row],[NHL_EQUIVALENT]] -> 0.1880597 | U45: =Table24[[#This Row],[G]]/Table24[[#This Row],[PTS]] -> 0.23809524 | V45: =Table24[[#This Row],[A]]/Table24[[#This Row],[PTS]] -> 0.76190476 | W45: 0 | X45: 0 | Y45: USA | Z45: #VALUE! | AA45: Henry Brzustewicz (D) | AB45: 39122 | AC45: 6'1" | AD45: 194 | AE45: R
... A50: 2025 | C50: Conrad Fondrk | D50: 49 | E50: F | F50: U.S. National U18 Team | G50: NTDP | H50: 0.28 | I50: 40 | J50: 13 | K50: 14 | L50: 27 | M50: 6 | N50: =Table24[[#This Row],[G]]/Table24[[#This Row],[GP]] -> 0.325 | O50: =Table24[[#This Row],[A]]/Table24[[#This Row],[GP]] -> 0.35 | P50: =Table24[[#This Row],[PTS]]/Table24[[#This Row],[GP]] -> 0.675 | Q50: =Table24[[#This Row],[PIM]]/Table24[[#This Row],[GP]] -> 0.15 | R50: =Table24[[#This Row],[PIM]]/Table24[[#This Row],[PTS]] -> 0.22222222 | S50: =Table24[[#This Row],[PTS]]/Table24[[#This Row],[PIM]] -> 4.5 | T50: =Table24[[#This Row],[PTS]]/Table24[[#This Row],[GP]]*Table24[[#This Row],[NHL_EQUIVALENT]] -> 0.189 | U50: =Table24[[#This Row],[G]]/Table24[[#This Row],[PTS]] -> 0.48148148 | V50: =Table24[[#This Row],[A]]/Table24[[#This Row],[PTS]] -> 0.51851852 | W50: 0 | X50: 0 | Y50: USA | Z50: #VALUE! | AA50: Conrad Fondrk (C) | AB50: 39234 | AC50: 6'0" | AD50: 192 | AE50: L
A51: 2025 | C51: Jack Ivankovic | D51: 50 | E51: G | F51: Brampton Steelheads | G51: OHL | H51: 0.3 | I51: 43 | J51: 0 | K51: 0 | L51: 0 | M51: 0 | N51: =Table24[[#This Row],[G]]/Table24[[#This Row],[GP]] -> 0 | O51: =Table24[[#This Row],[A]]/Table24[[#This Row],[GP]] -> 0 | P51: =Table24[[#This Row],[PTS]]/Table24[[#This Row],[GP]] -> 0 | Q51: =Table24[[#This Row],[PIM]]/Table24[[#This Row],[GP]] -> 0 | R51: 0 | S51: 0 | T51: =Table24[[#This Row],[PTS]]/Table24[[#This Row],[GP]]*Table24[[#This Row],[NHL_EQUIVALENT]] -> 0 | U51: 0 | V51: 0 | W51: 3.05 | X51: 0.903 | Y51: CANADA | Z51: #VALUE! | AA51: Jack Ivankovic (G) | AB51: 39224 | AC51: 6'0" | AD51: 179 | AE51: L
A52: 2025 | C52: Haoxi Wang | D52: 51 | E52: D | F52: Oshawa Generals | G52: OHL | H52: 0.3 | I52: 32 | J52: 0 | K52: 2 | L52: 2 | M52: 19 | N52: =Table24[[#This Row],[G]]/Table24[[#This Row],[GP]] -> 0 | O52: =Table24[[#This Row],[A]]/Table24[[#This Row],[GP]] -> 0.0625 | P52: =Table24[[#This Row],[PTS]]/Table24[[#This Row],[GP]] -> 0.0625 | Q52: =Table24[[#This Row],[PIM]]/Table24[[#This Row],[GP]] -> 0.59375 | R52: =Table24[[#This Row],[PIM]]/Table24[[#This Row],[PTS]] -> 9.5 | S52: =Table24[[#This Row],[PTS]]/Table24[[#This Row],[PIM]] -> 0.10526316 | T52: =Table24[[#This Row],[PTS]]/Table24[[#This Row],[GP]]*Table24[[#This Row],[NHL_EQUIVALENT]] -> 0.01875 | U52: =Table24[[#This Row],[G]]/Table24[[#This Row],[PTS]] -> 0 | V52: =Table24[[#This Row],[A]]/Table24[[#This Row],[PTS]] -> 1 | W52: 0 | X52: 0 | Y52: CHINA | Z52: #VALUE! | AA52: Haoxi Wang (D) | AB52: 39290 | AC52: 6'6" | AD52: 209 | AE52: L
A53: 2025 | C53: Luca Romano | D53: 52 | E53: F | F53: Kitchener Rangers | G53: OHL | H53: 0.3 | I53: 67 | J53: 25 | K53: 26 | L53: 51 | M53: 22 | N53: =Table24[[#This Row],[G]]/Table24[[#This Row],[GP]] -> 0.37313433 | O53: =Table24[[#This Row],[A]]/Table24[[#This Row],[GP]] -> 0.3880597 | P53: =Table24[[#This Row],[PTS]]/Table24[[#This Row],[GP]] -> 0.76119403 | Q53: =Table24[[#This Row],[PIM]]/Table24[[#This Row],[GP]] -> 0.32835821 | R53: =Table24[[#This Row],[PIM]]/Table24[[#This Row],[PTS]] -> 0.43137255 | S53: =Table24[[#This Row],[PTS]]/Table24[[#This Row],[PIM]] -> 2.3181818 | T53: =Table24[[#This Row],[PTS]]/Table24[[#This Row],[GP]]*Table24[[#This Row],[NHL_EQUIVALENT]] -> 0.22835821 | U53: =Table24[[#This Row],[G]]/Table24[[#This Row],[PTS]] -> 0.49019608 | V53: =Table24[[#This Row],[A]]/Table24[[#This Row],[PTS]] -> 0.50980392 | W53: 0 | X53: 0 | Y53: CANADA | Z53: #VALUE! | AA53: Luca Romano (C) | AB53: 39258 | AC53: 5'11" | AD53: 168 | AE53: R
A54: 2025 | C54: Vaclav Nestrasil | D54: 53 | E54: F | F54: Muskegon Lumberjacks | G54: USHL | H54: 0.27 | I54: 61 | J54: 19 | K54: 23 | L54: 42 | M54: 51 | N54: =Table24[[#This Row],[G]]/Table24[[#This Row],[GP]] -> 0.31147541 | O54: =Table24[[#This Row],[A]]/Table24[[#This Row],[GP]] -> 0.37704918 | P54: =Table24[[#This Row],[PTS]]/Table24[[#This Row],[GP]] -> 0.68852459 | Q54: =Table24[[#This Row],[PIM]]/Table24[[#This Row],[GP]] -> 0.83606557 | R54: =Table24[[#This Row],[PIM]]/Table24[[#This Row],[PTS]] -> 1.2142857 | S54: =Table24[[#This Row],[PTS]]/Table24[[#This Row],[PIM]] -> 0.82352941 | T54: =Table24[[#This Row],[PTS]]/Table24[[#This Row],[GP]]*Table24[[#This Row],[NHL_EQUIVALENT]] -> 0.18590164 | U54: =Table24[[#This Row],[G]]/Table24[[#This Row],[PTS]] -> 0.45238095 | V54: =Table24[[#This Row],[A]]/Table24[[#This Row],[PTS]] -> 0.54761905 | W54: 0 | X54: 0 | Y54: CZECHIA | Z54: #VALUE! | AA54: Vaclav Nestrasil (RW) | AB54: 39178 | AC54: 6'5" | AD54: 190 | AE54: R
A55: 2025 | C55: Ethan Czata | D55: 54 | E55: F | F55: Niagara IceDogs | G55: OHL | H55: 0.3 | I55: 68 | J55: 21 | K55: 34 | L55: 55 | M55: 72 | N55: =Table24[[#This Row],[G]]/Table24[[#This Row],[GP]] -> 0.30882353 | O55: =Table24[[#This Row],[A]]/Table24[[#This Row],[GP]] -> 0.5 | P55: =Table24[[#This Row],[PTS]]/Table24[[#This Row],[GP]] -> 0.80882353 | Q55: =Table24[[#This Row],[PIM]]/Table24[[#This Row],[GP]] -> 1.0588235 | R55: =Table24[[#This Row],[PIM]]/Table24[[#This Row],[PTS]] -> 1.3090909 | S55: =Table24[[#This Row],[PTS]]/Table24[[#This Row],[PIM]] -> 0.76388889 | T55: =Table24[[#This Row],[PTS]]/Table24[[#This Row],[GP]]*Table24[[#This Row],[NHL_EQUIVALENT]] -> 0.24264706 | U55: =Table24[[#This Row],[G]]/Table24[[#This Row],[PTS]] -> 0.38181818 | V55: =Table24[[#This Row],[A]]/Table24[[#This Row],[PTS]] -> 0.61818182 | W55: 0 | X55: 0 | Y55: CANADA | Z55: #VALUE! | AA55: Ethan Czata (C) | AB55: 39231 | AC55: 6'1" | AD55: 174 | AE55: L
A56: 2025 | C56: Viktor Klingsell | D56: 55 | E56: F | F56: SkellefteÃ¥ AIK J20 | G56: J20 Nationell | H56: 0.27 | I56: 43 | J56: 17 | K56: 22 | L56: 39 | M56: 6 | N56: =Table24[[#This Row],[G]]/Table24[[#This Row],[GP]] -> 0.39534884 | O56: =Table24[[#This Row],[A]]/Table24[[#This Row],[GP]] -> 0.51162791 | P56: =Table24[[#This Row],[PTS]]/Table24[[#This Row],[GP]] -> 0.90697674 | Q56: =Table24[[#This Row],[PIM]]/Table24[[#This Row],[GP]] -> 0.13953488 | R56: =Table24[[#This Row],[PIM]]/Table24[[#This Row],[PTS]] -> 0.15384615 | S56: =Table24[[#This Row],[PTS]]/Table24[[#This Row],[PIM]] -> 6.5 | T56: =Table24[[#This Row],[PTS]]/Table24[[#This Row],[GP]]*Table24[[#This Row],[NHL_EQUIVALENT]] -> 0.24488372 | U56: =Table24[[#This Row],[G]]/Table24[[#This Row],[PTS]] -> 0.43589744 | V56: =Table24[[#This Row],[A]]/Table24[[#This Row],[PTS]] -> 0.56410256 | W56: 0 | X56: 0 | Y56: SWEDEN | Z56: #VALUE! | AA56: Viktor Klingsell (LW) | AB56: 39123 | AC56: 5'10" | AD56: 183 | AE56: L
A57: 2025 | C57: Luka Radivojevic | D57: 56 | E57: D | F57: Muskegon Lumberjacks | G57: USHL | H57: 0.27 | I57: 38 | J57: 3 | K57: 19 | L57: 22 | M57: 39 | N57: =Table24[[#This Row],[G]]/Table24[[#This Row],[GP]] -> 0.078947368 | O57: =Table24[[#This Row],[A]]/Table24[[#This Row],[GP]] -> 0.5 | P57: =Table24[[#This Row],[PTS]]/Table24[[#This Row],[GP]] -> 0.57894737 | Q57: =Table24[[#This Row],[PIM]]/Table24[[#This Row],[GP]] -> 1.0263158 | R57: =Table24[[#This Row],[PIM]]/Table24[[#This Row],[PTS]] -> 1.7727273 | S57: =Table24[[#This Row],[PTS]]/Table24[[#This Row],[PIM]] -> 0.56410256 | T57: =Table24[[#This Row],[PTS]]/Table24[[#This Row],[GP]]*Table24[[#This Row],[NHL_EQUIVALENT]] -> 0.15631579 | U57: =Table24[[#This Row],[G]]/Table24[[#This Row],[PTS]] -> 0.13636364 | V57: =Table24[[#This Row],[A]]/Table24[[#This Row],[PTS]] -> 0.86363636 | W57: 0 | X57: 0 | Y57: SLOVAKIA | Z57: #VALUE! | AA57: Luka Radivojevic (D) | AB57: 39085 | AC57: 5'10" | AD57: 168 | AE57: R
A58: 2025 | C58: Matthew Gard | D58: 57 | E58: F | F58: Red Deer Rebels | G58: WHL | H58: 0.29 | I58: 66 | J58: 19 | K58: 17 | L58: 36 | M58: 81 | N58: =Table24[[#This Row],[G]]/Table24[[#This Row],[GP]] -> 0.28787879 | O58: =Table24[[#This Row],[A]]/Table24[[#This Row],[GP]] -> 0.25757576 | P58: =Table24[[#This Row],[PTS]]/Table24[[#This Row],[GP]] -> 0.54545455 | Q58: =Table24[[#This Row],[PIM]]/Table24[[#This Row],[GP]] -> 1.2272727 | R58: =Table24[[#This Row],[PIM]]/Table24[[#This Row],[PTS]] -> 2.25 | S58: =Table24[[#This Row],[PTS]]/Table24[[#This Row],[PIM]] -> 0.44444444 | T58: =Table24[[#This Row],[PTS]]/Table24[[#This Row],[GP]]*Table24[[#This Row],[NHL_EQUIVALENT]] -> 0.15818182 | U58: =Table24[[#This Row],[G]]/Table24[[#This Row],[PTS]] -> 0.52777778 | V58: =Table24[[#This Row],[A]]/Table24[[#This Row],[PTS]] -> 0.47222222 | W58: 0 | X58: 0 | Y58: CANADA | Z58: #VALUE! | AA58: Matthew Gard (F) | AB58: 39179 | AC58: 6'4" | AD58: 192 | AE58: L
A59: 2025 | C59: Kristian Epperson | D59: 58 | E59: F | F59: Saginaw Spirit | G59: OHL | H59: 0.3 | I59: 58 | J59: 27 | K59: 53 | L59: 80 | M59: 87 | N59: =Table24[[#This Row],[G]]/Table24[[#This Row],[GP]] -> 0.46551724 | O59: =Table24[[#This Row],[A]]/Table24[[#This Row],[GP]] -> 0.9137931 | P59: =Table24[[#This Row],[PTS]]/Table24[[#This Row],[GP]] -> 1.3793103 | Q59: =Table24[[#This Row],[PIM]]/Table24[[#This Row],[GP]] -> 1.5 | R59: =Table24[[#This Row],[PIM]]/Table24[[#This Row],[PTS]] -> 1.0875 | S59: =Table24[[#This Row],[PTS]]/Table24[[#This Row],[PIM]] -> 0.91954023 | T59: =Table24[[#This Row],[PTS]]/Table24[[#This Row],[GP]]*Table24[[#This Row],[NHL_EQUIVALENT]] -> 0.4137931 | U59: =Table24[[#This Row],[G]]/Table24[[#This Row],[PTS]] -> 0.3375 | V59: =Table24[[#This Row],[A]]/Table24[[#This Row],[PTS]] -> 0.6625 | W59: 0 | X59: 0 | Y59: USA | Z59: #VALUE! | AA59: Kristian Epperson (LW) | AB59: 38853 | AC59: 6'0" | AD59: 185 | AE59: L
A60: 2025 | C60: Arvid Drott | D60: 59 | E60: F | F60: Djurgardens IF J20 | G60: J20 Nationell | H60: 0.27 | I60: 40 | J60: 18 | K60: 18 | L60: 36 | M60: 14 | N60: =Table24[[#This Row],[G]]/Table24[[#This Row],[GP]] -> 0.45 | O60: =Table24[[#This Row],[A]]/Table24[[#This Row],[GP]] -> 0.45 | P60: =Table24[[#This Row],[PTS]]/Table24[[#This Row],[GP]] -> 0.9 | Q60: =Table24[[#This Row],[PIM]]/Table24[[#This Row],[GP]] -> 0.35 | R60: =Table24[[#This Row],[PIM]]/Table24[[#This Row],[PTS]] -> 0.38888889 | S60: =Table24[[#This Row],[PTS]]/Table24[[#This Row],[PIM]] -> 2.5714286 | T60: =Table24[[#This Row],[PTS]]/Table24[[#This Row],[GP]]*Table24[[#This Row],[NHL_EQUIVALENT]] -> 0.243 | U60: =Table24[[#This Row],[G]]/Table24[[#This Row],[PTS]] -> 0.5 | V60: =Table24[[#This Row],[A]]/Table24[[#This Row],[PTS]] -> 0.5 | W60: 0 | X60: 0 | Y60: SWEDEN | Z60: #VALUE! | AA60: Arvid Drott (RW) | AB60: 39305 | AC60: 6'1" | AD60: 187 | AE60: R
A61: 2025 | C61: Gustav Hillstrom | D61: 60 | E61: F | F61: Brynas IF J20 | G61: J20 Nationell | H61: 0.27 | I61: 43 | J61: 16 | K61: 22 | L61: 38 | M61: 16 | N61: =Table24[[#This Row],[G]]/Table24[[#This Row],[GP]] -> 0.37209302 | O61: =Table24[[#This Row],[A]]/Table24[[#This Row],[GP]] -> 0.51162791 | P61: =Table24[[#This Row],[PTS]]/Table24[[#This Row],[GP]] -> 0.88372093 | Q61: =Table24[[#This Row],[PIM]]/Table24[[#This Row],[GP]] -> 0.37209302 | R61: =Table24[[#This Row],[PIM]]/Table24[[#This Row],[PTS]] -> 0.42105263 | S61: =Table24[[#This Row],[PTS]]/Table24[[#This Row],[PIM]] -> 2.375 | T61: =Table24[[#This Row],[PTS]]/Table24[[#This Row],[GP]]*Table24[[#This Row],[NHL_EQUIVALENT]] -> 0.23860465 | U61: =Table24[[#This Row],[G]]/Table24[[#This Row],[PTS]] -> 0.42105263 | V61: =Table24[[#This Row],[A]]/Table24[[#This Row],[PTS]] -> 0.57894737 | W61: 0 | X61: 0 | Y61: SWEDEN | Z61: #VALUE! | AA61: Gustav Hillström (C) | AB61: 39102 | AC61: 6'2" | AD61: 176 | AE61: R
A62: 2025 | C62: Peyton Kettles | D62: 61 | E62: D | F62: Swift Current Broncos | G62: WHL | H62: 0.29 | I62: 53 | J62: 5 | K62: 9 | L62: 14 | M62: 65 | N62: =Table24[[#This Row],[G]]/Table24[[#This Row],[GP]] -> 0.094339623 | O62: =Table24[[#This Row],[A]]/Table24[[#This Row],[GP]] -> 0.16981132 | P62: =Table24[[#This Row],[PTS]]/Table24[[#This Row],[GP]] -> 0.26415094 | Q62: =Table24[[#This Row],[PIM]]/Table24[[#This Row],[GP]] -> 1.2264151 | R62: =Table24[[#This Row],[PIM]]/Table24[[#This Row],[PTS]] -> 4.6428571 | S62: =Table24[[#This Row],[PTS]]/Table24[[#This Row],[PIM]] -> 0.21538462 | T62: =Table24[[#This Row],[PTS]]/Table24[[#This Row],[GP]]*Table24[[#This Row],[NHL_EQUIVALENT]] -> 0.076603774 | U62: =Table24[[#This Row],[G]]/Table24[[#This Row],[PTS]] -> 0.35714286 | V62: =Table24[[#This Row],[A]]/Table24[[#This Row],[PTS]] -> 0.64285714 | W62: 0 | X62: 0 | Y62: CANADA | Z62: #VALUE! | AA62: Peyton Kettles (D) | AB62: 39326 | AC62: 6'5" | AD62: 194 | AE62: R
...

Sheet post_one_analysis
A1: PLAYER | B1: RANKING | C1: POSITION | D1: GPG | E1: APG | F1: PTSPG | G1: NHLe | H1: NATIONALITY | I1: FLAG | J1: HEIGHT | K1: WEIGHT | O1: PLAYER | P1: RANKING | Q1: POSITION | R1: GPG | S1: APG | T1: PTSPG | U1: NHLe | V1: NATIONALITY | W1: HEIGHT | X1: WEIGHT
A2: Matthew Schaefer | B2: 1 | C2: D | D2: =Table24[[#This Row],[G]]/Table24[[#This Row],[GP]] -> 0.41176471 | E2: =Table24[[#This Row],[A]]/Table24[[#This Row],[GP]] -> 0.88235294 | F2: =Table24[[#This Row],[PTS]]/Table24[[#This Row],[GP]] -> 1.2941176 | G2: =Table24[[#This Row],[PTS]]/Table24[[#This Row],[GP]]*Table24[[#This Row],[NHL_EQUIVALENT]] -> 0.38823529 | H2: CANADA | I2: #VALUE! | J2: 6'2" | K2: 183 | O2: Michael Misa | P2: 2 | Q2: F | R2: 0.95384615 | S2: 1.1076923 | T2: 2.0615385 | U2: 0.61846154 | V2: CANADA | W2: 6'1" | X2: 185
A3: Michael Misa | B3: 2 | C3: F | D3: =Table24[[#This Row],[G]]/Table24[[#This Row],[GP]] -> 0.95384615 | E3: =Table24[[#This Row],[A]]/Table24[[#This Row],[GP]] -> 1.1076923 | F3: =Table24[[#This Row],[PTS]]/Table24[[#This Row],[GP]] -> 2.0615385 | G3: =Table24[[#This Row],[PTS]]/Table24[[#This Row],[GP]]*Table24[[#This Row],[NHL_EQUIVALENT]] -> 0.61846154 | H3: CANADA | I3: #VALUE! | J3: 6'1" | K3: 185 | O3: Porter Martone | P3: 4 | Q3: F | R3: 0.64912281 | S3: 1.0701754 | T3: 1.7192982 | U3: 0.51578947 | V3: CANADA | W3: 6'3" | X3: 207
A4: James Hagens | B4: 3 | C4: F | D4: =Table24[[#This Row],[G]]/Table24[[#This Row],[GP]] -> 0.2972973 | E4: =Table24[[#This Row],[A]]/Table24[[#This Row],[GP]] -> 0.7027027 | F4: =Table24[[#This Row],[PTS]]/Table24[[#This Row],[GP]] -> 1 | G4: =Table24[[#This Row],[PTS]]/Table24[[#This Row],[GP]]*Table24[[#This Row],[NHL_EQUIVALENT]] -> 0.32 | H4: USA | I4: #VALUE! | J4: 5'11" | K4: 176 | O4: Jake O'Brien | P4: 10 | Q4: F | R4: 0.48484848 | S4: 1 | T4: 1.4848485 | U4: 0.44545455 | V4: CANADA | W4: 6'2" | X4: 170
A5: Porter Martone | B5: 4 | C5: F | D5: =Table24[[#This Row],[G]]/Table24[[#This Row],[GP]] -> 0.64912281 | E5: =Table24[[#This Row],[A]]/Table24[[#This Row],[GP]] -> 1.0701754 | F5: =Table24[[#This Row],[PTS]]/Table24[[#This Row],[GP]] -> 1.7192982 | G5: =Table24[[#This Row],[PTS]]/Table24[[#This Row],[GP]]*Table24[[#This Row],[NHL_EQUIVALENT]] -> 0.51578947 | H5: CANADA | I5: #VALUE! | J5: 6'3" | K5: 207 | O5: Benjamin Kindel | P5: 19 | Q5: F | R5: 0.53846154 | S5: 0.98461538 | T5: 1.5230769 | U5: 0.44169231 | V5: CANADA | W5: 5'10" | X5: 176
A6: Anton Frondell | B6: 5 | C6: F | D6: =Table24[[#This Row],[G]]/Table24[[#This Row],[GP]] -> 0.37931034 | E6: =Table24[[#This Row],[A]]/Table24[[#This Row],[GP]] -> 0.48275862 | F6: =Table24[[#This Row],[PTS]]/Table24[[#This Row],[GP]] -> 0.86206897 | G6: =Table24[[#This Row],[PTS]]/Table24[[#This Row],[GP]]*Table24[[#This Row],[NHL_EQUIVALENT]] -> 0.35344828 | H6: SWEDEN | I6: #VALUE! | J6: 6'0" | K6: 196 | O6: Cole Reschny | P6: 22 | Q6: F | R6: 0.41935484 | S6: 1.0645161 | T6: 1.483871 | U6: 0.43032258 | V6: CANADA | W6: 5'10" | X6: 187
A7: Roger McQueen | B7: 6 | C7: F | D7: =Table24[[#This Row],[G]]/Table24[[#This Row],[GP]] -> 0.58823529 | E7: =Table24[[#This Row],[A]]/Table24[[#This Row],[GP]] -> 0.58823529 | F7: =Table24[[#This Row],[PTS]]/Table24[[#This Row],[GP]] -> 1.1764706 | G7: =Table24[[#This Row],[PTS]]/Table24[[#This Row],[GP]]*Table24[[#This Row],[NHL_EQUIVALENT]] -> 0.34117647 | H7: CANADA | I7: #VALUE! | J7: 6'5" | K7: 192 | O7: Carter Bear | P7: 12 | Q7: F | R7: 0.71428571 | S7: 0.75 | T7: 1.4642857 | U7: 0.42464286 | V7: CANADA | W7: 6'0" | X7: 176
A8: Victor Eklund | B8: 7 | C8: F | D8: =Table24[[#This Row],[G]]/Table24[[#This Row],[GP]] -> 0.45238095 | E8: =Table24[[#This Row],[A]]/Table24[[#This Row],[GP]] -> 0.28571429 | F8: =Table24[[#This Row],[PTS]]/Table24[[#This Row],[GP]] -> 0.73809524 | G8: =Table24[[#This Row],[PTS]]/Table24[[#This Row],[GP]]*Table24[[#This Row],[NHL_EQUIVALENT]] -> 0.30261905 | H8: SWEDEN | I8: #VALUE! | J8: 5'11" | K8: 161 | O8: Caleb Desnoyers | P8: 8 | Q8: F | R8: 0.625 | S8: 0.875 | T8: 1.5 | U8: 0.405 | V8: CANADA | W8: 6'2" | X8: 172
A9: Caleb Desnoyers | B9: 8 | C9: F | D9: =Table24[[#This Row],[G]]/Table24[[#This Row],[GP]] -> 0.625 | E9: =Table24[[#This Row],[A]]/Table24[[#This Row],[GP]] -> 0.875 | F9: =Table24[[#This Row],[PTS]]/Table24[[#This Row],[GP]] -> 1.5 | G9: =Table24[[#This Row],[PTS]]/Table24[[#This Row],[GP]]*Table24[[#This Row],[NHL_EQUIVALENT]] -> 0.405 | H9: CANADA | I9: #VALUE! | J9: 6'2" | K9: 172 | O9: Matthew Schaefer | P9: 1 | Q9: D | R9: 0.41176471 | S9: 0.88235294 | T9: 1.2941176 | U9: 0.38823529 | V9: CANADA | W9: 6'2" | X9: 183
A10: Jackson Smith | B10: 9 | C10: D | D10: =Table24[[#This Row],[G]]/Table24[[#This Row],[GP]] -> 0.16176471 | E10: =Table24[[#This Row],[A]]/Table24[[#This Row],[GP]] -> 0.63235294 | F10: =Table24[[#This Row],[PTS]]/Table24[[#This Row],[GP]] -> 0.79411765 | G10: =Table24[[#This Row],[PTS]]/Table24[[#This Row],[GP]]*Table24[[#This Row],[NHL_EQUIVALENT]] -> 0.23029412 | H10: CANADA | I10: #VALUE! | J10: 6'3" | K10: 190 | O10: Justin Carbonneau | P10: 16 | Q10: F | R10: 0.74193548 | S10: 0.69354839 | T10: 1.4354839 | U10: 0.38758065 | V10: CANADA | W10: 6'1" | X10: 192
A11: Jake O'Brien | B11: 10 | C11: F | D11: =Table24[[#This Row],[G]]/Table24[[#This Row],[GP]] -> 0.48484848 | E11: =Table24[[#This Row],[A]]/Table24[[#This Row],[GP]] -> 1 | F11: =Table24[[#This Row],[PTS]]/Table24[[#This Row],[GP]] -> 1.4848485 | G11: =Table24[[#This Row],[PTS]]/Table24[[#This Row],[GP]]*Table24[[#This Row],[NHL_EQUIVALENT]] -> 0.44545455 | H11: CANADA | I11: #VALUE! | J11: 6'2" | K11: 170 | O11: Brady Martin | P11: 15 | Q11: F | R11: 0.57894737 | S11: 0.68421053 | T11: 1.2631579 | U11: 0.37894737 | V11: CANADA | W11: 6'0" | X11: 174
A12: Radim Mrtka | B12: 11 | C12: D | D12: =Table24[[#This Row],[G]]/Table24[[#This Row],[GP]] -> 0.069767442 | E12: =Table24[[#This Row],[A]]/Table24[[#This Row],[GP]] -> 0.74418605 | F12: =Table24[[#This Row],[PTS]]/Table24[[#This Row],[GP]] -> 0.81395349 | G12: =Table24[[#This Row],[PTS]]/Table24[[#This Row],[GP]]*Table24[[#This Row],[NHL_EQUIVALENT]] -> 0.23604651 | H12: CZECHIA | I12: #VALUE! | J12: 6'6" | K12: 216 | O12: Cameron Schmidt | P12: 25 | Q12: F | R12: 0.6557377 | S12: 0.62295082 | T12: 1.2786885 | U12: 0.37081967 | V12: CANADA | W12: 5'7" | X12: 157
